<?xml version='1.0'?>
<robot xmlns:xacro="http://www.ros.org/wiki/xacro" name="robot_car">


    <xacro:property name="blx" value="${0.10/10}" />  <!-- .origen chasis link.. -->  
    <xacro:property name="bly" value="${0.08/10}" />  <!-- .origen chasis link.. --> 
    <xacro:property name="blz" value="${0/10}" />   <!-- .origen chasis link.. --> 
    <xacro:property name="radio" value="${0.9/10}" />   <!-- radio base .. --> 
    <xacro:property name="ancho" value="${0.03/10}" /> <!-- ancho base.. --> 
   
    <xacro:property name="olx" value="${0.0/10}" />     <!-- despalazamiento de la llantas en x .. --> 
    <xacro:property name="oly" value="${0.92/10}" />   <!-- despalazamiento de la llantas en y. --> 
    <xacro:property name="olz" value="${0.0/10}" />  <!-- despalazamiento de la llantas en z. --> 

    <xacro:property name="crad" value="${0.43/2/10}" />  <!-- radio llanta. --> 
    <xacro:property name="clen" value="${0.09/10}" />  <!-- ancho llanta --> 
 
    <xacro:property name="srad" value="${0.2/2/10}" />  <!-- radio rueda loca --> 
    <xacro:property name="slx" value="${(1.6/2)/10}" />  <!--  despalazamiento de la rueda loca en x.--> 
    <xacro:property name="slz" value="${(0.08)/10}" />  <!--  despalazamiento de la rueda loca en z.-->

    <xacro:macro name="wheel_macro" params="p_name p_radius p_length">

        <link name="${p_name}">
        <!-- ... -->
            <visual>
            <!-- ... -->
            <!-- Box geometry -->
                <geometry>
                <!-- Unidades por defecto en metros -->
                    <cylinder radius="${p_radius}" length="${p_length}"/>
                </geometry>
                <origin xyz="0 0 0" rpy="-${pi/2} 0 0"/>
            </visual>
            <!-- Determina caracteristicas fisicas del robot -->
            <inertial>
            <!-- ... -->
                <mass value="1"/>
                <!-- Ubicacion del centro de masa -->
                <origin xyz="0 0 0" rpy="0 0 0"/>
                <!-- Tensor de inercia -->
                <inertia ixx="1" ixy="0" ixz="0" iyy="1" iyz="0" izz="1"/> <!-- buscar como es la inercia de una rueda -->
            </inertial>
            <!-- Esta parte define como interactua con otros objetos -->
            <collision>
            <!-- ... -->
            
            <!-- Unidades por defecto en metros -->
                <geometry>
                    <cylinder radius="${p_radius}" length="${p_length}"/>
                </geometry>
                <origin xyz="0 0 0" rpy="0 0 0"/>
            </collision>
        </link>
    </xacro:macro>

  <!-- ################-->
   

    <!-- ################-->
    <link name="world">
        <!-- ... -->
    </link>

    <joint name="world_worldx_joint" type="prismatic">
        <!-- ... -->
        <parent link="world"/>
        <child link="worldx"/>
        <axis xyz="1 0 0"/>
        <origin xyz="0 0 0" rpy="3.14 0 0"/>
        <limit effort="1" lower="-10" upper="10" velocity="10"/>
    </joint>

    <link name="worldx">
        <!-- ... -->
    </link>

    <joint name="worldx_worldy_joint" type="prismatic">
        <!-- ... -->
        <parent link="worldx"/>
        <child link="worldy"/>
        <axis xyz="0 1 0"/>
        <origin xyz="0 0 0" rpy="0 0 0"/>
        <limit effort="1" lower="-10" upper="10" velocity="10"/>
    </joint>

    <link name="worldy">
        <!-- ... -->
    </link>

    <joint name="worldy_worldth_joint" type="continuous">
        <!-- ... -->
        <parent link="worldy"/>
        <child link="worldth"/>
        <origin xyz="0 0 0" rpy="0 0 0"/>
        <axis xyz="0 0 1"/>
        <limit effort="1" lower="0" upper="${2*pi}" velocity="10"/>
    </joint>

    <link name="worldth">
        <!-- ... -->
    </link>

    <joint name="worldth_base_joint" type="fixed">
        <!-- ... -->
        <parent link="worldth"/>
        <child link="base_link"/>
        <origin xyz="0 0 0" rpy="0 3.1415 3.1415"/>
    </joint>

    
    <link name="base_link">
        <!-- ... -->
    </link>
    
    <joint name="base_chassis_joint" type="fixed">
        <!-- ... -->
        <parent link="base_link"/>
        <child link="chassis_link"/>
        <origin xyz="-${olx} 0 0" rpy="0 0 0"/>
    </joint>

    
    <link name="chassis_link">
        <!-- ... -->
        <visual>
            <!-- ... -->
            <!-- Box geometry -->
            <geometry>
                <!-- Unidades por defecto en metros -->
                <cylinder radius="${radio}" length="${ancho}"/>
            </geometry>
           
            <origin xyz="0 0 0" rpy="0 0 0"/>
        </visual>
        <!-- Determina caracteristicas fisicas del robot -->
        <inertial>
            <!-- ... -->
            <mass value="1"/>
            <!-- Ubicacion del centro de masa -->
            <origin xyz="0 0 0" rpy="0 0 0"/>
            <!-- Tensor de inercia -->
            <inertia ixx="1" ixy="0" ixz="0" iyy="1" iyz="0" izz="1"/>
        </inertial>
        <!-- Esta parte define como interactua con otros objetos -->
        <collision>
            <!-- ... -->
            
            <!-- Unidades por defecto en metros -->
            <geometry>
                 <cylinder radius="${radio}" length="${ancho}"/>
            </geometry>
            <origin xyz="${blx/2} 0 ${blz/2}" rpy="0 0 0"/>
        </collision>
    </link>
    <!-- ... -->
    <joint name="chassis_rwheel_joint" type="continuous">
        <parent link="chassis_link"/>
        <child link="rwheel_link"/>
        <origin xyz="${olx} ${oly} ${olz}" rpy="0 0 0"/>
        <axis xyz="0 1 0"/>
        <limit effort="1" lower="0" upper="${2*pi}" velocity="1"/>
        <dynamics damping="1" friction="1"/>  
    </joint>

    <xacro:wheel_macro p_name ="rwheel_link"
                       p_radius ="${crad}" 
                       p_length ="${clen}" />
  <!-- ... -->
     <joint name="chassis_lwheel_joint" type="continuous">
        <parent link="chassis_link"/>
        <child link="lwheel_link"/>
        <origin xyz="${olx} -${oly} ${olz}" rpy="0 0 0"/>
        <axis xyz="0 1 0"/>
        <limit effort="1" lower="0" upper="${2*pi}" velocity="1"/>
        <dynamics damping="1" friction="1"/>  
    </joint>

    <xacro:wheel_macro p_name ="lwheel_link"
                       p_radius ="${crad}" 
                       p_length ="${clen}" />


    <joint name="chassis_caster_joint" type="fixed">
        <parent link="chassis_link"/>
        <child link="caster_link"/>
        <origin xyz="${slx} 0 -${slz}" rpy="0 0 0"/>
        
    </joint>



    <link name="caster_link">
        <!-- ... -->
        <visual>
            <!-- ... -->
            <!-- Box geometry -->
            <geometry>
                <!-- Unidades por defecto en metros -->
                <sphere radius="${srad}"/>
            </geometry>
           
            <origin xyz="0 0 0" rpy="0 0 0"/>
        </visual>
        <!-- Determina caracteristicas fisicas del robot -->
        <inertial>
            <!-- ... -->
            <mass value="1"/>
            <!-- Ubicacion del centro de masa -->n
            <origin xyz="0 0 0" rpy="0 0 0"/>
            <!-- Tensor de inercia -->
            <inertia ixx="1" ixy="0" ixz="0" iyy="1" iyz="0" izz="1"/>
        </inertial>
        <!-- Esta parte define como interactua con otros objetos -->
        <collision>
            <!-- ... -->
            
            <!-- Unidades por defecto en metros -->
            <geometry>
                <sphere radius="${srad}"/>
            </geometry>
            <origin xyz="0 0 0" rpy="0 0 0"/>
        </collision>
    </link>

</robot>